Workbook
Name Slicer_Concerterntion_astrans: #N/A
Name Slicer_Growth: #N/A
Name Slicer_Region: #N/A
Name Slicer_Traiff_Catrgey: #N/A

Sheet Clean Data
A1: Importers | B1: Value imported in 2024 (USD thousand) | C1: Trade balance in 2024 (USD thousand) | D1: Quantity imported in 2024 | E1: Quantity Unit | F1: Unit value (USD/unit) | G1: Annual growth in value between 2020-2024 (%) | H1: Annual growth in quantity between 2020-2024 (%) | I1: Annual growth in value between 2023-2024 (%) | J1: Share in world imports (%) | K1: Average distance of supplying countries (km) | L1: Concentration of supplying countries | M1: Average tariff (estimated) applied by the country (%) | N1: Concerterntion astrans | O1: Region | P1: Growth | Q1: Traiff Catrgey
A2: Germany | B2: 91361 | C2: -25985 | D2: 341423 | E2: Tons | F2: 268 | G2: 8 | H2: 16 | I2: -9 | J2: 9 | K2: 660 | L2: 0.26 | M2: 1.8 | N2: =IF(Table1_1[[#This Row],[Concentration of supplying countries]]>0.5,"Manoply","Not Manoply") -> Not Manoply | O2: Western/Central Europe | P2: =IF(Table1_1[[#This Row],[Annual growth in quantity between 2020-2024 (%)]]>10%,"High Growth", IF(Table1_1[[#This Row],[Annual growth in quantity between 2020-2024 (%)]]>0,"Stable","Decline")) -> High Growth | Q2: =IF(Table1_1[[#This Row],[Average tariff (estimated) applied by the country (%)]]>1.8,"High","Low") -> Low
A3: United States of America | B3: 54248 | C3: -13806 | D3: 105800 | E3: Tons | F3: 513 | G3: 5 | H3: 3 | I3: 28 | J3: 5.3 | K3: 2918 | L3: 0.64 | M3: 1.8 | N3: =IF(Table1_1[[#This Row],[Concentration of supplying countries]]>0.5,"Manoply","Not Manoply") -> Manoply | O3: North America | P3: =IF(Table1_1[[#This Row],[Annual growth in quantity between 2020-2024 (%)]]>10%,"High Growth", IF(Table1_1[[#This Row],[Annual growth in quantity between 2020-2024 (%)]]>0,"Stable","Decline")) -> High Growth | Q3: =IF(Table1_1[[#This Row],[Average tariff (estimated) applied by the country (%)]]>1.8,"High","Low") -> Low
A4: Italy | B4: 50769 | C4: -50762 | D4: 97632 | E4: No quantity | F4: 520 | G4: 6 | H4: 4 | I4: 2 | J4: 5 | K4: 825 | L4: 0.19 | M4: 1.8 | N4: =IF(Table1_1[[#This Row],[Concentration of supplying countries]]>0.5,"Manoply","Not Manoply") -> Not Manoply | O4: Southern Europe | P4: =IF(Table1_1[[#This Row],[Annual growth in quantity between 2020-2024 (%)]]>10%,"High Growth", IF(Table1_1[[#This Row],[Annual growth in quantity between 2020-2024 (%)]]>0,"Stable","Decline")) -> High Growth | Q4: =IF(Table1_1[[#This Row],[Average tariff (estimated) applied by the country (%)]]>1.8,"High","Low") -> Low
A5: France | B5: 41958 | C5: -2345 | D5: 62054 | E5: Tons | F5: 676 | G5: 8 | H5: 0 | I5: 3 | J5: 4.1 | K5: 689 | L5: 0.25 | M5: 1.8 | N5: =IF(Table1_1[[#This Row],[Concentration of supplying countries]]>0.5,"Manoply","Not Manoply") -> Not Manoply | O5: Western Europe | P5: =IF(Table1_1[[#This Row],[Annual growth in quantity between 2020-2024 (%)]]>10%,"High Growth", IF(Table1_1[[#This Row],[Annual growth in quantity between 2020-2024 (%)]]>0,"Stable","Decline")) -> Decline | Q5: =IF(Table1_1[[#This Row],[Average tariff (estimated) applied by the country (%)]]>1.8,"High","Low") -> Low
A6: Israel | B6: 38792 | C6: -33359 | D6: 62769 | E6: Tons | F6: 618 | G6: 13 | H6: 4 | I6: 10 | J6: 3.8 | K6: 3515 | L6: 0.46 | M6: 1.8 | N6: =IF(Table1_1[[#This Row],[Concentration of supplying countries]]>0.5,"Manoply","Not Manoply") -> Not Manoply | O6: Western Asia (Middle East) | P6: =IF(Table1_1[[#This Row],[Annual growth in quantity between 2020-2024 (%)]]>10%,"High Growth", IF(Table1_1[[#This Row],[Annual growth in quantity between 2020-2024 (%)]]>0,"Stable","Decline")) -> High Growth | Q6: =IF(Table1_1[[#This Row],[Average tariff (estimated) applied by the country (%)]]>1.8,"High","Low") -> Low
A7: Viet Nam | B7: 34586 | C7: -33906 | D7: 55396 | E7: Tons | F7: 624 | G7: 9 | H7: 1 | I7: -9 | J7: 3.4 | K7: 1916 | L7: 0.31 | M7: 2.1 | N7: =IF(Table1_1[[#This Row],[Concentration of supplying countries]]>0.5,"Manoply","Not Manoply") -> Not Manoply | O7: Southeast Asia | P7: =IF(Table1_1[[#This Row],[Annual growth in quantity between 2020-2024 (%)]]>10%,"High Growth", IF(Table1_1[[#This Row],[Annual growth in quantity between 2020-2024 (%)]]>0,"Stable","Decline")) -> High Growth | Q7: =IF(Table1_1[[#This Row],[Average tariff (estimated) applied by the country (%)]]>1.8,"High","Low") -> High
A8: Taipei, Chinese | B8: 33727 | C8: -27402 | D8: 52012 | E8: Tons | F8: 648 | G8: -7 | H8: -12 | I8: -15 | J8: 3.3 | K8: 1880 | L8: 0.42 | M8: 4.1 | N8: =IF(Table1_1[[#This Row],[Concentration of supplying countries]]>0.5,"Manoply","Not Manoply") -> Not Manoply | O8: East Asia | P8: =IF(Table1_1[[#This Row],[Annual growth in quantity between 2020-2024 (%)]]>10%,"High Growth", IF(Table1_1[[#This Row],[Annual growth in quantity between 2020-2024 (%)]]>0,"Stable","Decline")) -> Decline | Q8: =IF(Table1_1[[#This Row],[Average tariff (estimated) applied by the country (%)]]>1.8,"High","Low") -> High
A9: United Kingdom | B9: 33184 | C9: -29494 | D9: 52702 | E9: Tons | F9: 630 | G9: 43 | H9: 44 | I9: 19 | J9: 3.3 | K9: 789 | L9: 0.37 | M9: 1.1 | N9: =IF(Table1_1[[#This Row],[Concentration of supplying countries]]>0.5,"Manoply","Not Manoply") -> Not Manoply | O9: Western Europe | P9: =IF(Table1_1[[#This Row],[Annual growth in quantity between 2020-2024 (%)]]>10%,"High Growth", IF(Table1_1[[#This Row],[Annual growth in quantity between 2020-2024 (%)]]>0,"Stable","Decline")) -> High Growth | Q9: =IF(Table1_1[[#This Row],[Average tariff (estimated) applied by the country (%)]]>1.8,"High","Low") -> Low
A10: Belgium | B10: 27445 | C10: 108092 | D10: 46793 | E10: Tons | F10: 587 | G10: 11 | H10: 15 | I10: -11 | J10: 2.7 | K10: 863 | L10: 0.28 | M10: 1.8 | N10: =IF(Table1_1[[#This Row],[Concentration of supplying countries]]>0.5,"Manoply","Not Manoply") -> Not Manoply | O10: Western Europe | P10: =IF(Table1_1[[#This Row],[Annual growth in quantity between 2020-2024 (%)]]>10%,"High Growth", IF(Table1_1[[#This Row],[Annual growth in quantity between 2020-2024 (%)]]>0,"Stable","Decline")) -> High Growth | Q10: =IF(Table1_1[[#This Row],[Average tariff (estimated) applied by the country (%)]]>1.8,"High","Low") -> Low
A11: Austria | B11: 26701 | C11: 4369 | D11: 48547 | E11: No quantity | F11: 550 | G11: 13 | H11: 4 | I11: 4 | J11: 2.6 | K11: 655 | L11: 0.39 | M11: 1.8 | N11: =IF(Table1_1[[#This Row],[Concentration of supplying countries]]>0.5,"Manoply","Not Manoply") -> Not Manoply | O11: Western/Central Europe | P11: =IF(Table1_1[[#This Row],[Annual growth in quantity between 2020-2024 (%)]]>10%,"High Growth", IF(Table1_1[[#This Row],[Annual growth in quantity between 2020-2024 (%)]]>0,"Stable","Decline")) -> High Growth | Q11: =IF(Table1_1[[#This Row],[Average tariff (estimated) applied by the country (%)]]>1.8,"High","Low") -> Low
A12: Netherlands | B12: 26482 | C12: 69914 | D12: 46337 | E12: Tons | F12: 572 | G12: 2 | H12: -8 | I12: -12 | J12: 2.6 | K12: 585 | L12: 0.47 | M12: 1.8 | N12: =IF(Table1_1[[#This Row],[Concentration of supplying countries]]>0.5,"Manoply","Not Manoply") -> Not Manoply | O12: Western Europe | P12: =IF(Table1_1[[#This Row],[Annual growth in quantity between 2020-2024 (%)]]>10%,"High Growth", IF(Table1_1[[#This Row],[Annual growth in quantity between 2020-2024 (%)]]>0,"Stable","Decline")) -> Decline | Q12: =IF(Table1_1[[#This Row],[Average tariff (estimated) applied by the country (%)]]>1.8,"High","Low") -> Low
A13: Ireland | B13: 24830 | C13: -24572 | D13: 17230 | E13: Tons | F13: 1441 | G13: 17 | H13: -3 | I13: -4 | J13: 2.4 | K13: 2900 | L13: 0.5 | M13: 1.8 | N13: =IF(Table1_1[[#This Row],[Concentration of supplying countries]]>0.5,"Manoply","Not Manoply") -> Not Manoply | O13: Western Europe | P13: =IF(Table1_1[[#This Row],[Annual growth in quantity between 2020-2024 (%)]]>10%,"High Growth", IF(Table1_1[[#This Row],[Annual growth in quantity between 2020-2024 (%)]]>0,"Stable","Decline")) -> Decline | Q13: =IF(Table1_1[[#This Row],[Average tariff (estimated) applied by the country (%)]]>1.8,"High","Low") -> Low
... A172: Sao Tome and Principe | B172: 5 | C172: -5 | D172: 3 | E172: Tons | F172: 1667 | G172: 6 | H172: 1 | I172: 132 | J172: 0 | K172: 4615 | L172: 1 | M172: 5 | N172: =IF(Table1_1[[#This Row],[Concentration of supplying countries]]>0.5,"Manoply","Not Manoply") -> Manoply | O172: Central Africa | P172: =IF(Table1_1[[#This Row],[Annual growth in quantity between 2020-2024 (%)]]>10%,"High Growth", IF(Table1_1[[#This Row],[Annual growth in quantity between 2020-2024 (%)]]>0,"Stable","Decline")) -> High Growth | Q172: =IF(Table1_1[[#This Row],[Average tariff (estimated) applied by the country (%)]]>1.8,"High","Low") -> High

Sheet Phase1
A1: Phase 1 :
B3: 1. What is the size of the global market for Hydrogen Peroxide?
A5: Row Labels | B5: Sum of Value imported in 2024 (USD thousand)
A6: Ecuador | B6: 9890
A7: Japan | B7: 10298
A8: Poland | B8: 11640
A9: Türkiye | B9: 13886
A10: India | B10: 16016
A11: Peru | B11: 17334
A12: Czech Republic | B12: 19180
A13: Spain | B13: 19724
A14: Singapore | B14: 22002
A15: Portugal | B15: 22266
A16: Indonesia | B16: 22859
A17: Mexico | B17: 24112
... A26: Grand Total | B26: 566293
B30: 2. Which countries represent the largest import markets?
A32: Row Labels | B32: Sum of Value imported in 2024 (USD thousand)
A33: Germany | B33: 91361
A34: United States of America | B34: 54248
A35: Italy | B35: 50769
A36: Israel | B36: 38792
A37: Viet Nam | B37: 34586
A38: United Kingdom | B38: 33184
A39: Belgium | B39: 27445
A40: Austria | B40: 26701
A41: Mexico | B41: 24112
A42: Indonesia | B42: 22859
A43: Grand Total | B43: 404057
B46: 3. Are global import values and quantities increasing in recent years?
A47: Row Labels | B47: Average of Annual growth in value between 2020-2024 (%) | C47: Average of Annual growth in quantity between 2020-2024 (%)
A48: Benin | B48: 156 | C48: 329
A49: Mauritania | B49: 116 | C49: 4
A50: Ship stores and bunkers | B50: 59 | C50: 4
A51: Panama | B51: 56 | C51: 59
A52: Senegal | B52: 55 | C52: 63
A53: Namibia | B53: 55 | C53: 50
A54: Venezuela, Bolivarian Republic of | B54: 46 | C54: 19
A55: New Caledonia | B55: 45 | C55: 4
A56: Cambodia | B56: 45 | C56: 46
...

Sheet Phase2
A1: Top importer | B1: Dynamic | C1: Actual market | D1: Target market | E1: Type | F1: supply conc
A2: Germany | B2: Benin | C2: Jordan | D2: Cyprus | E2: AD | F2: 0.45
A3: United States of America | B3: Jamaica | C3: South Africa | D3: Madagascar | E3: AD | F3: 0.5
A4: Italy | B4: Aruba | C4: Türkiye | D4: Uganda | E4: AD | F4: 0.32
A5: France | B5: Senegal | C5: India | D5: Jordan | E5: TA | F5: 0.46
A6: Israel | B6: Panama | C6: Pakistan | D6: India | E6: TA | F6: 0.67
A7: Viet Nam | B7: Suriname | C7: Morocco | D7: Türkiye | E7: TA | F7: 0.46
A8: Taipei, Chinese | B8: Namibia | C8: Cyprus | D8: Russian Federation | E8: TA | F8: 0.22
A9: United Kingdom | B9: Cambodia | C9: Russian Federation | D9: Italy | E9: TA | F9: 0.19
A10: Belgium | B10: United Kingdom | C10: Italy | D10: Germany | E10: TD | F10: 0.26
A11: Austria | B11: Nepal | C11: Madagascar | D11: United Arab Emirates | E11: A | F11: 0.26
A12: Netherlands | B12: Algeria | C12: Uganda | D12: South Africa | E12: A | F12: 0.29
A13: Ireland | B13: Zambia | C13: United Arab Emirates | D13: Pakistan | E13: A | F13: 0.51
A14: Mexico | B14: Georgia | D14: Morocco | E14: A | F14: 0.26
A15: Indonesia | B15: Brazil | D15: Algeria | E15: D | F15: 0.24
A16: Portugal | B16: Fiji | D16: Indonesia | E16: T | F16: 0.33
A17: Singapore | B17: Uzbekistan
A18: Chile | B18: Latvia
A19: Spain | B19: Cyprus
A20: Czech Republic | B20: Djibouti
A21: Peru | B21: Australia
A22: Argentina | B22: Tajikistan
A23: India | B23: Papua New Guinea
A24: China | B24: Philippines
A25: Sweden | B25: Paraguay
A26: Switzerland | B26: Angola
A27: Türkiye | B27: Lebanon
A28: Malaysia | B28: Rwanda
... A40: Hungary | B40: Iceland

Sheet Phase3
A1: Target country | B1: Column2 | C1: Column3 | D1: Column4 | E1: Column5 | F1: Column6 | G1: Column7 | H1: Column8 | I1: Column9 | J1: Column10 | K1: Column11 | L1: Column12 | N1: Compitatores
A2: Cyprus | B2: Belgium | C2: Netherlands | D2: Greece | E2: Slovenia | F2: Germany | G2: United Kingdom | N2: Belgium | O2: =SUMIF(B2:G21,"Belgium",B3:G21) -> 231.1
B3: 64.4 | C3: 9.8 | D3: 9.8 | E3: 9.8 | F3: 5.9 | G3: 0.5 | N3: Korea, Republic of | O3: =SUMIF(B4:L20,"Korea, Republic of",B5:L21) -> 127.8
A4: Madagascar | B4: Korea, Republic of | C4: India | D4: Taipei, Chinese | E4: China | F4: France | G4: Mauritius | H4: Italy | N4: India | O4: =SUMIF(B4:J21,"India",B5:J21) -> 116.2
B5: 68.9 | C5: 11 | D5: 9.2 | E5: 7.5 | F5: 2.2 | G5: 0.9 | H5: 0.4 | N5: Bangladesh | O5: =SUMIF(B2:L20,"Bangladesh",B3:L21) -> 80.6
A6: Uganda | B6: India | C6: China | D6: Korea, Republic of | E6: Israel | F6: Kenya | N6: Netherlands | O6: =SUMIF(C2:J20,"Netherlands",C3:J21) -> 65.9
B7: 33.5 | C7: 33.1 | D7: 31.7 | E7: 1.6 | F7: 0.2 | N7: China | O7: 64
A8: Jordan | B8: Israel | C8: Belgium | D8: Egypt | E8: Korea, Republic of | F8: Saudi Arabia | G8: Türkiye | H8: Netherlands | I8: Thailand | J8: India | K8: Germany | L8: United States of America | N8: Israel | O8: =SUMIF(B6:E8,"Israel",B7:E9) -> 55.4
B9: 53.8 | C9: 41.2 | D9: 1.6 | E9: 1.1 | F9: 0.7 | G9: 0.5 | H9: 0.3 | I9: 0.2 | J9: 0.2 | K9: 0.2 | L9: 0.2 | N9: Austria | O9: =SUMIF(B2:L20,"Austria",B3:L21) -> 38.8
A10: India | B10: Bangladesh | C10: Thailand | D10: China | E10: Belgium | F10: United States of America | G10: Türkiye | H10: Malaysia | I10: United Kingdom | J10: Netherlands | K10: Germany | L10: United Arab Emirates | N10: Sweden | O10: =SUMIF(C2:L20,"Sweden",C3:L21) -> 30.7
B11: 80.6 | C11: 14.3 | D11: 1.8 | E11: 1.2 | F11: 1 | G11: 0.2 | H11: 0.2 | I11: 0.2 | J11: 0.1 | K11: 0.1 | L11: 0.1 | N11: France | O11: =SUMIF(B2:L20,"France",B3:L21) -> 28
A12: Türkiye | B12: Belgium | C12: Sweden | D12: Netherlands | E12: Finland | F12: India | G12: Austria | H12: Germany | I12: United Kingdom | J12: France | K12: China | L12: Italy | N12: Germany | O12: =SUMIF(C2:K20,"Germany",C3:K21) -> 27.3
B13: 64.2 | C13: 17.7 | D13: 10.3 | E13: 2.6 | F13: 2.1 | G13: 1.1 | H13: 0.7 | I13: 0.5 | J13: 0.4 | K13: 0.3 | L13: 0 | N13: Türkiye | O13: =SUMIF(B2:L20,"Türkiye",B3:L21) -> 26.4
A14: Russian Federation | B14: India | C14: Türkiye | D14: Korea, Republic of | E14: China | F14: Uzbekistan | G14: Hungary | H14: Armenia | I14: Denmark | J14: Taipei, Chinese | K14: Kazakhstan | L14: Kyrgyzstan
B15: 24.7 | C15: 24.4 | D15: 22.4 | E15: 21.3 | F15: 5.2 | G15: 1.4 | H15: 0.4 | I15: 0.1 | J15: 0 | K15: 0
A16: Italy | B16: Austria | C16: Germany | D16: Slovenia | E16: France | F16: Sweden | G16: Belgium | H16: Netherlands | I16: Switzerland | J16: United States of America | K16: Spain | L16: Korea, Republic of
B17: 30.9 | C17: 19 | D17: 17.1 | E17: 12.6 | F17: 9.9 | G17: 5.7 | H17: 2.5 | I17: 1.5 | J17: 0.3 | K17: 0.2 | L17: 0.1
A18: Germany | B18: Belgium | C18: Netherlands | D18: France | E18: Austria | F18: Finland | G18: Italy | H18: Sweden | I18: Australia | J18: Switzerland | K18: Japan | L18: Poland
B19: 38.1 | C19: 30.9 | D19: 11.3 | E19: 6.8 | F19: 3.9 | G19: 3.3 | H19: 3.1 | I19: 1.1 | J19: 0.3 | K19: 0.3 | L19: 0.3
A20: United Arab Emirates | B20: India | C20: Belgium | D20: Netherlands | E20: Saudi Arabia | F20: Korea, Republic of | G20: United States of America | H20: Pakistan | I20: France | J20: Germany | K20: Türkiye | L20: Taipei, Chinese
B21: 44.7 | C21: 16.3 | D21: 12 | E21: 12 | F21: 3.6 | G21: 3.1 | H21: 2.7 | I21: 1.5 | J21: 1.4 | K21: 1.3 | L21: 0.5

Sheet Sheet2
A1: Importers | B1: Sum of Value imported in 2024 (USD thousand)
A2: =Phase1!A6 -> Ecuador | B2: =GETPIVOTDATA("Sum of Value imported in 2024 (USD thousand)",Phase1!$B$5,"Importers",A2) -> 9890
A3: =Phase1!A7 -> Japan | B3: =GETPIVOTDATA("Sum of Value imported in 2024 (USD thousand)",Phase1!$B$5,"Importers",A3) -> 10298
A4: =Phase1!A8 -> Poland | B4: =GETPIVOTDATA("Sum of Value imported in 2024 (USD thousand)",Phase1!$B$5,"Importers",A4) -> 11640
A5: =Phase1!A9 -> Türkiye | B5: =GETPIVOTDATA("Sum of Value imported in 2024 (USD thousand)",Phase1!$B$5,"Importers",A5) -> 13886
A6: =Phase1!A10 -> India | B6: =GETPIVOTDATA("Sum of Value imported in 2024 (USD thousand)",Phase1!$B$5,"Importers",A6) -> 16016
A7: =Phase1!A11 -> Peru | B7: =GETPIVOTDATA("Sum of Value imported in 2024 (USD thousand)",Phase1!$B$5,"Importers",A7) -> 17334
A8: =Phase1!A12 -> Czech Republic | B8: =GETPIVOTDATA("Sum of Value imported in 2024 (USD thousand)",Phase1!$B$5,"Importers",A8) -> 19180
A9: =Phase1!A13 -> Spain | B9: =GETPIVOTDATA("Sum of Value imported in 2024 (USD thousand)",Phase1!$B$5,"Importers",A9) -> 19724
A10: =Phase1!A14 -> Singapore | B10: =GETPIVOTDATA("Sum of Value imported in 2024 (USD thousand)",Phase1!$B$5,"Importers",A10) -> 22002
A11: =Phase1!A15 -> Portugal | B11: =GETPIVOTDATA("Sum of Value imported in 2024 (USD thousand)",Phase1!$B$5,"Importers",A11) -> 22266
A12: =Phase1!A16 -> Indonesia | B12: =GETPIVOTDATA("Sum of Value imported in 2024 (USD thousand)",Phase1!$B$5,"Importers",A12) -> 22859
A13: =Phase1!A17 -> Mexico | B13: =GETPIVOTDATA("Sum of Value imported in 2024 (USD thousand)",Phase1!$B$5,"Importers",A13) -> 24112
... A21: =Phase1!A25 -> Germany | B21: =GETPIVOTDATA("Sum of Value imported in 2024 (USD thousand)",Phase1!$B$5,"Importers",A21) -> 91361

Sheet Dashboard

Sheet Sheet1
A1: Row Labels | B1: Sum of Value imported in 2024 (USD thousand)
A2: Ecuador | B2: 9890
A3: Japan | B3: 10298
A4: Poland | B4: 11640
A5: Türkiye | B5: 13886
A6: India | B6: 16016
A7: Peru | B7: 17334
A8: Czech Republic | B8: 19180
A9: Spain | B9: 19724
A10: Singapore | B10: 22002
A11: Portugal | B11: 22266
A12: Indonesia | B12: 22859
A13: Mexico | B13: 24112
... A22: Grand Total | B22: 566293

Sheet Draft phasa2
A1: Importers | B1: Concentration of supplying countries | G1: Target Market | H1: Heirarcey | I1: supply conc
A2: Germany | B2: 0.26 | G2: Cyprus | H2: AD | I2: =VLOOKUP(G2,Table58[#All],2,0) -> 0.45
A3: United States of America | B3: 0.64 | G3: Madagascar | H3: AD | I3: =VLOOKUP(G3,Table58[#All],2,0) -> 0.5
A4: Italy | B4: 0.19 | G4: Uganda | H4: AD | I4: =VLOOKUP(G4,Table58[#All],2,0) -> 0.32
A5: France | B5: 0.25 | G5: Jordan | H5: TA | I5: =VLOOKUP(G5,Table58[#All],2,0) -> 0.46
A6: Israel | B6: 0.46 | G6: India | H6: TA | I6: =VLOOKUP(G6,Table58[#All],2,0) -> 0.67
A7: Viet Nam | B7: 0.31 | G7: Türkiye | H7: TA | I7: =VLOOKUP(G7,Table58[#All],2,0) -> 0.46
A8: Taipei, Chinese | B8: 0.42 | G8: Russian Federation | H8: TA | I8: =VLOOKUP(G8,Table58[#All],2,0) -> 0.22
A9: United Kingdom | B9: 0.37 | G9: Italy | H9: TA | I9: =VLOOKUP(G9,Table58[#All],2,0) -> 0.19
A10: Belgium | B10: 0.28 | G10: Germany | H10: TA | I10: =VLOOKUP(G10,Table58[#All],2,0) -> 0.26
A11: Austria | B11: 0.39 | G11: United Arab Emirates | H11: A | I11: =VLOOKUP(G11,Table58[#All],2,0) -> 0.26
A12: Netherlands | B12: 0.47 | G12: South Africa | H12: A | I12: =VLOOKUP(G12,Table58[#All],2,0) -> 0.29
A13: Ireland | B13: 0.5 | G13: Pakistan | H13: A | I13: =VLOOKUP(G13,Table58[#All],2,0) -> 0.51
... A16: Portugal | B16: 0.22 | G16: Indonesia | H16: T | I16: =VLOOKUP(G16,Table58[#All],2,0) -> 0.33
A17: Singapore | B17: 0.39
A18: Chile | B18: 0.85
A19: Spain | B19: 0.2
A20: Czech Republic | B20: 0.61
A21: Peru | B21: 0.56
A22: Argentina | B22: 0.65
A23: India | B23: 0.67
A24: China | B24: 0.37
A25: Sweden | B25: 0.53
A26: Switzerland | B26: 0.32
A27: Türkiye | B27: 0.46
A28: Malaysia | B28: 0.22
... A172: Sao Tome and Principe | B172: 1

Sheet Trade_Map
A1: Importers | B1: Value imported in 2024 (USD thousand) | C1: Trade balance in 2024 (USD thousand) | D1: Quantity imported in 2024 | E1: Quantity Unit | F1: Unit value (USD/unit) | G1: Annual growth in value between 2020-2024 (%) | H1: Annual growth in quantity between 2020-2024 (%) | I1: Annual growth in value between 2023-2024 (%) | J1: Share in world imports (%) | K1: Average distance of supplying countries (km) | L1: Concentration of supplying countries | M1: Average tariff (estimated) applied by the country (%)
A2: Germany | B2: 91361 | C2: -25985 | D2: 341423 | E2: Tons | F2: 268 | G2: 8 | H2: 16 | I2: -9 | J2: 9 | K2: 660 | L2: 0.26 | M2: 1.8
A3: United States of America | B3: 54248 | C3: -13806 | D3: 105800 | E3: Tons | F3: 513 | G3: 5 | H3: 3 | I3: 28 | J3: 5.3 | K3: 2918 | L3: 0.64 | M3: 1.8
A4: Italy | B4: 50769 | C4: -50762 | D4: 97632 | E4: No quantity | F4: 520 | G4: 6 | I4: 2 | J4: 5 | K4: 825 | L4: 0.19 | M4: 1.8
A5: France | B5: 41958 | C5: -2345 | D5: 62054 | E5: Tons | F5: 676 | G5: 8 | H5: 0 | I5: 3 | J5: 4.1 | K5: 689 | L5: 0.25 | M5: 1.8
A6: Israel | B6: 38792 | C6: -33359 | D6: 62769 | E6: Tons | F6: 618 | G6: 13 | H6: 4 | I6: 10 | J6: 3.8 | K6: 3515 | L6: 0.46 | M6: ...
A7: Viet Nam | B7: 34586 | C7: -33906 | D7: 55396 | E7: Tons | F7: 624 | G7: 9 | H7: 1 | I7: -9 | J7: 3.4 | K7: 1916 | L7: 0.31 | M7: 2.1
A8: Taipei, Chinese | B8: 33727 | C8: -27402 | D8: 52012 | E8: Tons | F8: 648 | G8: -7 | H8: -12 | I8: -15 | J8: 3.3 | K8: 1880 | L8: 0.42 | M8: 4.1
A9: United Kingdom | B9: 33184 | C9: -29494 | D9: 52702 | E9: Tons | F9: 630 | G9: 43 | H9: 44 | I9: 19 | J9: 3.3 | K9: 789 | L9: 0.37 | M9: 1.1
A10: Belgium | B10: 27445 | C10: 108092 | D10: 46793 | E10: Tons | F10: 587 | G10: 11 | H10: 15 | I10: -11 | J10: 2.7 | K10: 863 | L10: 0.28 | M10: 1.8
A11: Austria | B11: 26701 | C11: 4369 | D11: 48547 | E11: No quantity | F11: 550 | G11: 13 | I11: 4 | J11: 2.6 | K11: 655 | L11: 0.39 | M11: 1.8
A12: Netherlands | B12: 26482 | C12: 69914 | D12: 46337 | E12: Tons | F12: 572 | G12: 2 | H12: -8 | I12: -12 | J12: 2.6 | K12: 585 | L12: 0.47 | M12: 1.8
A13: Ireland | B13: 24830 | C13: -24572 | D13: 17230 | E13: Tons | F13: 1441 | G13: 17 | H13: -3 | I13: -4 | J13: 2.4 | K13: 2900 | L13: 0.5 | M13: 1.8
A14: Mexico | B14: 24112 | C14: -23263 | D14: 44997 | E14: Tons | F14: 536 | G14: 4 | H14: 1 | I14: 6 | J14: 2.4 | K14: 1635 | L14: 1 | M14: 0
A15: Indonesia | B15: 22859 | C15: -10206 | D15: 49812 | E15: Tons | F15: 459 | G15: 11 | H15: 8 | I15: 7 | J15: 2.2 | K15: 3575 | L15: 0.33 | M15: 4.6
A16: Portugal | B16: 22266 | C16: -19119 | D16: 37739 | E16: No quantity | F16: 590 | G16: 12 | I16: -1 | J16: 2.2 | K16: 1604 | L16: 0.22 | M16: 1.8
A17: Singapore | B17: 22002 | C17: -9505 | D17: 27871 | E17: Tons | F17: 789 | G17: 13 | H17: 8 | I17: 12 | J17: 2.2 | K17: 1722 | L17: 0.39 | M17: 0
A18: Chile | B18: 21184 | C18: -20096 | D18: 48505 | E18: Tons | F18: 437 | G18: -3 | H18: -6 | I18: -11 | J18: 2.1 | K18: 4114 | L18: 0.85 | M18: 3.2
A19: Spain | B19: 19724 | C19: -10783 | D19: 38675 | E19: No quantity | F19: 510 | G19: 11 | I19: 26 | J19: 1.9 | K19: 1241 | L19: 0.2 | M19: 1.8
A20: Czech Republic | B20: 19180 | C20: -18583 | D20: 39958 | E20: No quantity | F20: 480 | G20: 7 | I20: 11 | J20: 1.9 | K20: 499 | L20: 0.61 | M20: 1.8
A21: Peru | B21: 17334 | C21: -17327 | D21: 28472 | E21: Tons | F21: 609 | G21: 11 | H21: 3 | I21: -9 | J21: 1.7 | K21: 5979 | L21: 0.56 | M21: 0
A22: Argentina | B22: 17123 | C22: -17123 | D22: 24420 | E22: Tons | F22: 701 | G22: 0 | H22: -7 | I22: -25 | J22: 1.7 | K22: 3340 | L22: 0.65 | M22: 9.5
A23: India | B23: 16016 | C23: -4412 | D23: 46171 | E23: Tons | F23: 347 | G23: 3 | H23: 8 | I23: -4 | J23: 1.6 | K23: 1616 | L23: 0.67 | M23: 5.9
A24: China | B24: 15912 | C24: -5068 | D24: 17749 | E24: Tons | F24: 897 | G24: -20 | H24: -23 | I24: -7 | J24: 1.6 | K24: 2454 | L24: 0.37 | M24: 5.9
A25: Sweden | B25: 15121 | C25: 37147 | D25: 42683 | E25: Tons | F25: 354 | G25: -4 | H25: 0 | I25: 30 | J25: 1.5 | K25: 585 | L25: 0.53 | M25: 1.8
A26: Switzerland | B26: 14334 | C26: -12728 | D26: 18980 | E26: Tons | F26: 755 | G26: 5 | H26: -3 | I26: -18 | J26: 1.4 | K26: 600 | L26: 0.32 | M26: 0
A27: Türkiye | B27: 13886 | C27: -784 | D27: 25858 | E27: No quantity | F27: 537 | G27: -4 | I27: -13 | J27: 1.4 | K27: 2489 | L27: 0.46 | M27: 2.7
A28: Malaysia | B28: 13109 | C28: -12460 | D28: 19624 | E28: Tons | F28: 668 | G28: 2 | H28: -3 | I28: -17 | J28: 1.3 | K28: 2721 | L28: 0.22 | M28: 0
A29: Colombia | B29: 12760 | C29: -12713 | D29: 21046 | E29: Tons | F29: 606 | G29: 2 | H29: -3 | I29: -8 | J29: 1.3 | K29: 5022 | L29: 0.61 | M29: 0
A30: Canada | B30: 11868 | C30: 31469 | D30: 6416 | E30: Tons | F30: 1850 | G30: -7 | H30: -18 | I30: 5 | J30: 1.2 | K30: 2323 | L30: 0.65 | M30: 0.3
A31: Poland | B31: 11640 | C31: -6995 | D31: 25554 | E31: Tons | F31: 456 | G31: 10 | H31: 5 | I31: -14 | J31: 1.1 | K31: 836 | L31: 0.23 | M31: 1.8
A32: Japan | B32: 10298 | C32: 6183 | D32: 23294 | E32: Tons | F32: 442 | G32: -1 | H32: 3 | I32: 8 | J32: 1 | K32: 1338 | L32: 0.75 | M32: 0.9
A33: Ecuador | B33: 9890 | C33: -9497 | D33: 18215 | E33: Tons | F33: 543 | G33: 3 | H33: 3 | I33: -51 | J33: 1 | K33: 7679 | L33: 0.51 | M33: 0
A34: Russian Federation | B34: 9204 | C34: -5721 | D34: 40368 | E34: No quantity | F34: 228 | G34: 17 | I34: -71 | J34: 0.9 | K34: 4037 | L34: 0.22 | M34: 4.8
A35: Philippines | B35: 9200 | C35: -9200 | D35: 18062 | E35: Tons | F35: 509 | G35: 22 | H35: 20 | I35: 10 | J35: 0.9 | K35: 2675 | L35: 0.42 | M35: 2.7
A36: Australia | B36: 8648 | C36: -5223 | D36: 17053 | E36: Tons | F36: 507 | G36: 27 | H36: 24 | I36: -5 | J36: 0.8 | K36: 7318 | L36: 0.24 | M36: 3.1
A37: Jordan | B37: 8513 | C37: -8513 | D37: 14991 | E37: Tons | F37: 568 | G37: 13 | H37: 13 | I37: 2 | J37: 0.8 | K37: 1601 | L37: 0.46 | M37: 0
A38: Slovakia | B38: 7397 | C38: -7086 | D38: 15572 | E38: No quantity | F38: 475 | G38: 0 | I38: 0 | J38: 0.7 | K38: 895 | L38: 0.43 | M38: 1.8
A39: Estonia | B39: 7283 | C39: -7254 | D39: 14280 | E39: No quantity | F39: 510 | G39: -6 | I39: 1 | J39: 0.7 | K39: 491 | L39: 0.4 | M39: 1.8
A40: Hungary | B40: 6809 | C40: -6135 | D40: 14692 | E40: Tons | F40: 463 | G40: 2 | H40: -2 | I40: 28 | J40: 0.7 | K40: 459 | L40: 0.28 | M40: 1.8
...
