Workbook
Name Slicer_Distance_category: #N/A
Name Slicer_Price_Category: #N/A
Name Slicer_score: #N/A
Name Slicer_Tariff_Category: #N/A

Sheet compartive analysis ph4
A1: Importers | B1: Value imported in 2024 (USD thousand) | C1: Trade balance in 2024 (USD thousand) | D1: Quantity imported in 2024 | E1: Quantity Unit | F1: Unit value (USD/unit) | G1: Annual growth in value between 2020-2024 (%) | H1: Annual growth in quantity between 2020-2024 (%) | I1: Annual growth in value between 2023-2024 (%) | J1: Share in world imports (%) | K1: Average distance of supplying countries (km) | L1: Concentration of supplying countries | M1: Average tariff (estimated) applied by the country (%)
A2: Germany | B2: 91361 | C2: -25985 | D2: 341423 | E2: Tons | F2: 268 | G2: 8 | H2: 16 | I2: -9 | J2: 9 | K2: 660 | L2: 0.26 | M2: 1.8
A3: United States of America | B3: 54248 | C3: -13806 | D3: 105800 | E3: Tons | F3: 513 | G3: 5 | H3: 3 | I3: 28 | J3: 5.3 | K3: 2918 | L3: 0.64 | M3: 1.8 | O3: Compitatores | P3: Distance | Q3: Price | R3: Tariff | S3: Price Category | T3: Tariff Category
A4: Italy | B4: 50769 | C4: -50762 | D4: 97632 | E4: No quantity | F4: 520 | G4: 6 | H4: 4 | I4: 2 | J4: 5 | K4: 825 | L4: 0.19 | M4: 1.8 | O4: Belgium | P4: =VLOOKUP(Table9[[#This Row],[Compitatores]],Table1_19[#All],11,0) -> 863 | Q4: =VLOOKUP(Table9[[#This Row],[Compitatores]],Table1_19[#All],6,0) -> 587 | R4: =VLOOKUP(Table9[[#This Row],[Compitatores]],Table1_19[],13,0) -> 1.8 | S4: =IF(Table9[[#This Row],[Price]]>750,"High price","Law price") -> Law price | T4: =IF(Table9[[#This Row],[Tariff]]>1.8,"High Tariff","Law Tariff") -> Law Tariff
A5: France | B5: 41958 | C5: -2345 | D5: 62054 | E5: Tons | F5: 676 | G5: 8 | H5: 0 | I5: 3 | J5: 4.1 | K5: 689 | L5: 0.25 | M5: 1.8 | O5: Korea, Republic of | P5: =VLOOKUP(Table9[[#This Row],[Compitatores]],Table1_19[#All],11,0) -> 6019 | Q5: =VLOOKUP(Table9[[#This Row],[Compitatores]],Table1_19[#All],6,0) -> 1686 | R5: =VLOOKUP(Table9[[#This Row],[Compitatores]],Table1_19[],13,0) -> 3.1 | S5: =IF(Table9[[#This Row],[Price]]>750,"High price","Law price") -> High price | T5: =IF(Table9[[#This Row],[Tariff]]>1.8,"High Tariff","Law Tariff") -> High Tariff
A6: Israel | B6: 38792 | C6: -33359 | D6: 62769 | E6: Tons | F6: 618 | G6: 13 | H6: 4 | I6: 10 | J6: 3.8 | K6: 3515 | L6: 0.46 | M6: 1.8 | O6: India | P6: =VLOOKUP(Table9[[#This Row],[Compitatores]],Table1_19[#All],11,0) -> 1616 | Q6: =VLOOKUP(Table9[[#This Row],[Compitatores]],Table1_19[#All],6,0) -> 347 | R6: =VLOOKUP(Table9[[#This Row],[Compitatores]],Table1_19[],13,0) -> 5.9 | S6: =IF(Table9[[#This Row],[Price]]>750,"High price","Law price") -> Law price | T6: =IF(Table9[[#This Row],[Tariff]]>1.8,"High Tariff","Law Tariff") -> High Tariff
A7: Viet Nam | B7: 34586 | C7: -33906 | D7: 55396 | E7: Tons | F7: 624 | G7: 9 | H7: 1 | I7: -9 | J7: 3.4 | K7: 1916 | L7: 0.31 | M7: 2.1 | O7: Bangladesh | P7: =VLOOKUP(Table9[[#This Row],[Compitatores]],Table1_19[#All],11,0) -> 2020 | Q7: =VLOOKUP(Table9[[#This Row],[Compitatores]],Table1_19[#All],6,0) -> 1004 | R7: =VLOOKUP(Table9[[#This Row],[Compitatores]],Table1_19[],13,0) -> 10 | S7: =IF(Table9[[#This Row],[Price]]>750,"High price","Law price") -> High price | T7: =IF(Table9[[#This Row],[Tariff]]>1.8,"High Tariff","Law Tariff") -> High Tariff
A8: Taipei, Chinese | B8: 33727 | C8: -27402 | D8: 52012 | E8: Tons | F8: 648 | G8: -7 | H8: -12 | I8: -15 | J8: 3.3 | K8: 1880 | L8: 0.42 | M8: 4.1 | O8: Netherlands | P8: =VLOOKUP(Table9[[#This Row],[Compitatores]],Table1_19[#All],11,0) -> 585 | Q8: =VLOOKUP(Table9[[#This Row],[Compitatores]],Table1_19[#All],6,0) -> 572 | R8: =VLOOKUP(Table9[[#This Row],[Compitatores]],Table1_19[],13,0) -> 1.8 | S8: =IF(Table9[[#This Row],[Price]]>750,"High price","Law price") -> Law price | T8: =IF(Table9[[#This Row],[Tariff]]>1.8,"High Tariff","Law Tariff") -> Law Tariff
A9: United Kingdom | B9: 33184 | C9: -29494 | D9: 52702 | E9: Tons | F9: 630 | G9: 43 | H9: 44 | I9: 19 | J9: 3.3 | K9: 789 | L9: 0.37 | M9: 1.1 | O9: China | P9: =VLOOKUP(Table9[[#This Row],[Compitatores]],Table1_19[#All],11,0) -> 2454 | Q9: =VLOOKUP(Table9[[#This Row],[Compitatores]],Table1_19[#All],6,0) -> 897 | R9: =VLOOKUP(Table9[[#This Row],[Compitatores]],Table1_19[],13,0) -> 5.9 | S9: =IF(Table9[[#This Row],[Price]]>750,"High price","Law price") -> High price | T9: =IF(Table9[[#This Row],[Tariff]]>1.8,"High Tariff","Law Tariff") -> High Tariff
A10: Belgium | B10: 27445 | C10: 108092 | D10: 46793 | E10: Tons | F10: 587 | G10: 11 | H10: 15 | I10: -11 | J10: 2.7 | K10: 863 | L10: 0.28 | M10: 1.8 | O10: Israel | P10: =VLOOKUP(Table9[[#This Row],[Compitatores]],Table1_19[#All],11,0) -> 3515 | Q10: =VLOOKUP(Table9[[#This Row],[Compitatores]],Table1_19[#All],6,0) -> 618 | R10: =VLOOKUP(Table9[[#This Row],[Compitatores]],Table1_19[],13,0) -> 1.8 | S10: =IF(Table9[[#This Row],[Price]]>750,"High price","Law price") -> Law price | T10: =IF(Table9[[#This Row],[Tariff]]>1.8,"High Tariff","Law Tariff") -> Law Tariff
A11: Austria | B11: 26701 | C11: 4369 | D11: 48547 | E11: No quantity | F11: 550 | G11: 13 | H11: 4 | I11: 4 | J11: 2.6 | K11: 655 | L11: 0.39 | M11: 1.8 | O11: Austria | P11: =VLOOKUP(Table9[[#This Row],[Compitatores]],Table1_19[#All],11,0) -> 655 | Q11: =VLOOKUP(Table9[[#This Row],[Compitatores]],Table1_19[#All],6,0) -> 550 | R11: =VLOOKUP(Table9[[#This Row],[Compitatores]],Table1_19[],13,0) -> 1.8 | S11: =IF(Table9[[#This Row],[Price]]>750,"High price","Law price") -> Law price | T11: =IF(Table9[[#This Row],[Tariff]]>1.8,"High Tariff","Law Tariff") -> Law Tariff
A12: Netherlands | B12: 26482 | C12: 69914 | D12: 46337 | E12: Tons | F12: 572 | G12: 2 | H12: -8 | I12: -12 | J12: 2.6 | K12: 585 | L12: 0.47 | M12: 1.8 | O12: Sweden | P12: =VLOOKUP(Table9[[#This Row],[Compitatores]],Table1_19[#All],11,0) -> 585 | Q12: =VLOOKUP(Table9[[#This Row],[Compitatores]],Table1_19[#All],6,0) -> 354 | R12: =VLOOKUP(Table9[[#This Row],[Compitatores]],Table1_19[],13,0) -> 1.8 | S12: =IF(Table9[[#This Row],[Price]]>750,"High price","Law price") -> Law price | T12: =IF(Table9[[#This Row],[Tariff]]>1.8,"High Tariff","Law Tariff") -> Law Tariff
A13: Ireland | B13: 24830 | C13: -24572 | D13: 17230 | E13: Tons | F13: 1441 | G13: 17 | H13: -3 | I13: -4 | J13: 2.4 | K13: 2900 | L13: 0.5 | M13: 1.8 | O13: France | P13: =VLOOKUP(Table9[[#This Row],[Compitatores]],Table1_19[#All],11,0) -> 689 | Q13: =VLOOKUP(Table9[[#This Row],[Compitatores]],Table1_19[#All],6,0) -> 676 | R13: =VLOOKUP(Table9[[#This Row],[Compitatores]],Table1_19[],13,0) -> 1.8 | S13: =IF(Table9[[#This Row],[Price]]>750,"High price","Law price") -> Law price | T13: =IF(Table9[[#This Row],[Tariff]]>1.8,"High Tariff","Law Tariff") -> Law Tariff
A14: Mexico | B14: 24112 | C14: -23263 | D14: 44997 | E14: Tons | F14: 536 | G14: 4 | H14: 1 | I14: 6 | J14: 2.4 | K14: 1635 | L14: 1 | M14: 0 | O14: Germany | P14: =VLOOKUP(Table9[[#This Row],[Compitatores]],Table1_19[#All],11,0) -> 660 | Q14: =VLOOKUP(Table9[[#This Row],[Compitatores]],Table1_19[#All],6,0) -> 268 | R14: =VLOOKUP(Table9[[#This Row],[Compitatores]],Table1_19[],13,0) -> 1.8 | S14: =IF(Table9[[#This Row],[Price]]>750,"High price","Law price") -> Law price | T14: =IF(Table9[[#This Row],[Tariff]]>1.8,"High Tariff","Law Tariff") -> Law Tariff
A15: Indonesia | B15: 22859 | C15: -10206 | D15: 49812 | E15: Tons | F15: 459 | G15: 11 | H15: 8 | I15: 7 | J15: 2.2 | K15: 3575 | L15: 0.33 | M15: 4.6 | O15: Türkiye | P15: =VLOOKUP(Table9[[#This Row],[Compitatores]],Table1_19[#All],11,0) -> 2489 | Q15: =VLOOKUP(Table9[[#This Row],[Compitatores]],Table1_19[#All],6,0) -> 537 | R15: =VLOOKUP(Table9[[#This Row],[Compitatores]],Table1_19[],13,0) -> 2.7 | S15: =IF(Table9[[#This Row],[Price]]>750,"High price","Law price") -> Law price | T15: =IF(Table9[[#This Row],[Tariff]]>1.8,"High Tariff","Law Tariff") -> High Tariff
A16: Portugal | B16: 22266 | C16: -19119 | D16: 37739 | E16: No quantity | F16: 590 | G16: 12 | H16: 4 | I16: -1 | J16: 2.2 | K16: 1604 | L16: 0.22 | M16: 1.8 | O16: Egypt | P16: =VLOOKUP(Table9[[#This Row],[Compitatores]],Table1_19[#All],11,0) -> 2776 | Q16: =VLOOKUP(Table9[[#This Row],[Compitatores]],Table1_19[#All],6,0) -> 610 | R16: =VLOOKUP(Table9[[#This Row],[Compitatores]],Table1_19[],13,0) -> 0 | S16: =IF(Table9[[#This Row],[Price]]>750,"High price","Law price") -> Law price | T16: =IF(Table9[[#This Row],[Tariff]]>1.8,"High Tariff","Law Tariff") -> Law Tariff
A17: Singapore | B17: 22002 | C17: -9505 | D17: 27871 | E17: Tons | F17: 789 | G17: 13 | H17: 8 | I17: 12 | J17: 2.2 | K17: 1722 | L17: 0.39 | M17: 0
A18: Chile | B18: 21184 | C18: -20096 | D18: 48505 | E18: Tons | F18: 437 | G18: -3 | H18: -6 | I18: -11 | J18: 2.1 | K18: 4114 | L18: 0.85 | M18: 3.2 | P18: average price for compeitator market | Q18: =MEDIAN(Table9[Price]) -> 587 | R18: =MEDIAN(Table9[Tariff]) -> 1.8
A19: Spain | B19: 19724 | C19: -10783 | D19: 38675 | E19: No quantity | F19: 510 | G19: 11 | H19: 4 | I19: 26 | J19: 1.9 | K19: 1241 | L19: 0.2 | M19: 1.8
A20: Czech Republic | B20: 19180 | C20: -18583 | D20: 39958 | E20: No quantity | F20: 480 | G20: 7 | H20: 4 | I20: 11 | J20: 1.9 | K20: 499 | L20: 0.61 | M20: 1.8
A21: Peru | B21: 17334 | C21: -17327 | D21: 28472 | E21: Tons | F21: 609 | G21: 11 | H21: 3 | I21: -9 | J21: 1.7 | K21: 5979 | L21: 0.56 | M21: 0
A22: Argentina | B22: 17123 | C22: -17123 | D22: 24420 | E22: Tons | F22: 701 | G22: 0 | H22: -7 | I22: -25 | J22: 1.7 | K22: 3340 | L22: 0.65 | M22: 9.5
A23: India | B23: 16016 | C23: -4412 | D23: 46171 | E23: Tons | F23: 347 | G23: 3 | H23: 8 | I23: -4 | J23: 1.6 | K23: 1616 | L23: 0.67 | M23: 5.9
A24: China | B24: 15912 | C24: -5068 | D24: 17749 | E24: Tons | F24: 897 | G24: -20 | H24: -23 | I24: -7 | J24: 1.6 | K24: 2454 | L24: 0.37 | M24: 5.9
A25: Sweden | B25: 15121 | C25: 37147 | D25: 42683 | E25: Tons | F25: 354 | G25: -4 | H25: 0 | I25: 30 | J25: 1.5 | K25: 585 | L25: 0.53 | M25: 1.8
A26: Switzerland | B26: 14334 | C26: -12728 | D26: 18980 | E26: Tons | F26: 755 | G26: 5 | H26: -3 | I26: -18 | J26: 1.4 | K26: 600 | L26: 0.32 | M26: 0
A27: Türkiye | B27: 13886 | C27: -784 | D27: 25858 | E27: No quantity | F27: 537 | G27: -4 | H27: 4 | I27: -13 | J27: 1.4 | K27: 2489 | L27: 0.46 | M27: 2.7
A28: Malaysia | B28: 13109 | C28: -12460 | D28: 19624 | E28: Tons | F28: 668 | G28: 2 | H28: -3 | I28: -17 | J28: 1.3 | K28: 2721 | L28: 0.22 | M28: 0
A29: Colombia | B29: 12760 | C29: -12713 | D29: 21046 | E29: Tons | F29: 606 | G29: 2 | H29: -3 | I29: -8 | J29: 1.3 | K29: 5022 | L29: 0.61 | M29: 0
A30: Canada | B30: 11868 | C30: 31469 | D30: 6416 | E30: Tons | F30: 1850 | G30: -7 | H30: -18 | I30: 5 | J30: 1.2 | K30: 2323 | L30: 0.65 | M30: 0.3
... A172: Sao Tome and Principe | B172: 5 | C172: -5 | D172: 3 | E172: Tons | F172: 1667 | G172: 6 | H172: 1 | I172: 132 | J172: 0 | K172: 4615 | L172: 1 | M172: 5
F173: =MEDIAN(Table1_19[Unit value (USD/unit)]) -> 750

Sheet pivot  ph4
A2: Phase 4
A3: Row Labels | B3: Sum of Price | D3: 1. How does Egypt compare with these competitors in terms of export price?
A4: Germany | B4: 268
A5: India | B5: 347
A6: Sweden | B6: 354
A7: Türkiye | B7: 537
A8: Austria | B8: 550
A9: Netherlands | B9: 572
A10: Belgium | B10: 587
A11: Egypt | B11: 610
A12: Israel | B12: 618
A13: France | B13: 676
A14: China | B14: 897
A15: Bangladesh | B15: 1004
A16: Korea, Republic of | B16: 1686
A17: Grand Total | B17: 8706 | C17: =GETPIVOTDATA("Price",$A$3) -> 8706
D20: 2. Does Egypt have a geographical advantage in terms of distance or logistics?
A22: Row Labels | B22: Sum of Distance
A23: Austria | B23: 655
A24: Bangladesh | B24: 2020
A25: Belgium | B25: 863
A26: China | B26: 2454
A27: Egypt | B27: 2776
A28: France | B28: 689
A29: Germany | B29: 660
A30: India | B30: 1616
A31: Israel | B31: 3515
A32: Korea, Republic of | B32: 6019
A33: Netherlands | B33: 585
A34: Sweden | B34: 585
... A36: Grand Total | B36: 24926
D39: 3. Are there favorable trade agreements or lower tariffs for Egyptian exports?
A41: Row Labels | B41: Sum of Tariff
A42: Egypt | B42: 0
A43: Germany | B43: 1.8
A44: Belgium | B44: 1.8
A45: Israel | B45: 1.8
A46: France | B46: 1.8
A47: Austria | B47: 1.8
A48: Netherlands | B48: 1.8
...

Sheet phase 5 draft
A1: Importers | B1: Value imported in 2024 (USD thousand) | C1: Trade balance in 2024 (USD thousand) | D1: Quantity imported in 2024 | E1: Quantity Unit | F1: Unit value (USD/unit) | G1: Annual growth in value between 2020-2024 (%) | H1: Annual growth in quantity between 2020-2024 (%) | I1: Annual growth in value between 2023-2024 (%) | J1: Share in world imports (%) | K1: Average distance of supplying countries (km) | L1: Concentration of supplying countries | M1: Average tariff (estimated) applied by the country (%) | R1: Drawing Map table target
A2: Germany | B2: 91361 | C2: -25985 | D2: 341423 | E2: Tons | F2: 268 | G2: 8 | H2: 16 | I2: -9 | J2: 9 | K2: 660 | L2: 0.26 | M2: 1.8 | O2: How can each target market be evaluated based on factors such as market size, market growth, competition intensity, distance, and tariffs?
A3: United States of America | B3: 54248 | C3: -13806 | D3: 105800 | E3: Tons | F3: 513 | G3: 5 | H3: 3 | I3: 28 | J3: 5.3 | K3: 2918 | L3: 0.64 | M3: 1.8 | O3: target | P3: quantity | Q3: value | R3: supplyconc | S3: Distance between target and egypy | T3: growth | U3: score | V3: Distance category
A4: Italy | B4: 50769 | C4: -50762 | D4: 97632 | E4: No quantity | F4: 520 | G4: 6 | H4: 4 | I4: 2 | J4: 5 | K4: 825 | L4: 0.19 | M4: 1.8 | O4: Cyprus | P4: =VLOOKUP(Table12[[#This Row],[target]],Table1_111[#All],4,0) -> 249 | Q4: =VLOOKUP(Table12[[#This Row],[target]],Table1_111[#All],2,0) -> 205 | R4: =VLOOKUP(Table12[[#This Row],[target]],Table1_111[#All],12,0) -> 0.45 | S4: 398 | T4: =VLOOKUP(Table12[[#This Row],[target]],Table1_111[#All],7,0) -> 24 | U4: =VLOOKUP(Table12[[#This Row],[target]],Table1917[#All],7,0) -> Export | V4: =IF(Table12[[#This Row],[Distance between target and egypy]]<=2000,"Close",IF(Table12[[#This Row],[Distance between target and egypy]]<=4000,"Medium","Far")) -> Close | X4: Compitatores | Y4: share
A5: France | B5: 41958 | C5: -2345 | D5: 62054 | E5: Tons | F5: 676 | G5: 8 | H5: 0 | I5: 3 | J5: 4.1 | K5: 689 | L5: 0.25 | M5: 1.8 | O5: Madagascar | P5: =VLOOKUP(Table12[[#This Row],[target]],Table1_111[#All],4,0) -> 393 | Q5: =VLOOKUP(Table12[[#This Row],[target]],Table1_111[#All],2,0) -> 228 | R5: =VLOOKUP(Table12[[#This Row],[target]],Table1_111[#All],12,0) -> 0.5 | S5: 6667 | T5: =VLOOKUP(Table12[[#This Row],[target]],Table1_111[#All],7,0) -> 17 | U5: =VLOOKUP(Table12[[#This Row],[target]],Table1917[#All],7,0) -> Not | V5: =IF(Table12[[#This Row],[Distance between target and egypy]]<=2000,"Close",IF(Table12[[#This Row],[Distance between target and egypy]]<=4000,"Medium","Far")) -> Far | X5: Belgium | Y5: =VLOOKUP(Table14[[#This Row],[Compitatores]],Table1_111[#All],9,0) -> -11
A6: Israel | B6: 38792 | C6: -33359 | D6: 62769 | E6: Tons | F6: 618 | G6: 13 | H6: 4 | I6: 10 | J6: 3.8 | K6: 3515 | L6: 0.46 | M6: 1.8 | O6: Uganda | P6: =VLOOKUP(Table12[[#This Row],[target]],Table1_111[#All],4,0) -> 1243 | Q6: =VLOOKUP(Table12[[#This Row],[target]],Table1_111[#All],2,0) -> 559 | R6: =VLOOKUP(Table12[[#This Row],[target]],Table1_111[#All],12,0) -> 0.32 | S6: 4650 | T6: =VLOOKUP(Table12[[#This Row],[target]],Table1_111[#All],7,0) -> 28 | U6: =VLOOKUP(Table12[[#This Row],[target]],Table1917[#All],7,0) -> Not | V6: =IF(Table12[[#This Row],[Distance between target and egypy]]<=2000,"Close",IF(Table12[[#This Row],[Distance between target and egypy]]<=4000,"Medium","Far")) -> Far | X6: Korea, Republic of | Y6: =VLOOKUP(Table14[[#This Row],[Compitatores]],Table1_111[#All],9,0) -> -9
A7: Viet Nam | B7: 34586 | C7: -33906 | D7: 55396 | E7: Tons | F7: 624 | G7: 9 | H7: 1 | I7: -9 | J7: 3.4 | K7: 1916 | L7: 0.31 | M7: 2.1 | O7: Jordan | P7: =VLOOKUP(Table12[[#This Row],[target]],Table1_111[#All],4,0) -> 14991 | Q7: =VLOOKUP(Table12[[#This Row],[target]],Table1_111[#All],2,0) -> 8513 | R7: =VLOOKUP(Table12[[#This Row],[target]],Table1_111[#All],12,0) -> 0.46 | S7: 205 | T7: =VLOOKUP(Table12[[#This Row],[target]],Table1_111[#All],7,0) -> 13 | U7: =VLOOKUP(Table12[[#This Row],[target]],Table1917[#All],7,0) -> Export | V7: =IF(Table12[[#This Row],[Distance between target and egypy]]<=2000,"Close",IF(Table12[[#This Row],[Distance between target and egypy]]<=4000,"Medium","Far")) -> Close | X7: India | Y7: =VLOOKUP(Table14[[#This Row],[Compitatores]],Table1_111[#All],9,0) -> -4
A8: Taipei, Chinese | B8: 33727 | C8: -27402 | D8: 52012 | E8: Tons | F8: 648 | G8: -7 | H8: -12 | I8: -15 | J8: 3.3 | K8: 1880 | L8: 0.42 | M8: 4.1 | O8: India | P8: =VLOOKUP(Table12[[#This Row],[target]],Table1_111[#All],4,0) -> 46171 | Q8: =VLOOKUP(Table12[[#This Row],[target]],Table1_111[#All],2,0) -> 16016 | R8: =VLOOKUP(Table12[[#This Row],[target]],Table1_111[#All],12,0) -> 0.67 | S8: 5200 | T8: =VLOOKUP(Table12[[#This Row],[target]],Table1_111[#All],7,0) -> 3 | U8: =VLOOKUP(Table12[[#This Row],[target]],Table1917[#All],7,0) -> Export | V8: =IF(Table12[[#This Row],[Distance between target and egypy]]<=2000,"Close",IF(Table12[[#This Row],[Distance between target and egypy]]<=4000,"Medium","Far")) -> Far | X8: Bangladesh | Y8: =VLOOKUP(Table14[[#This Row],[Compitatores]],Table1_111[#All],9,0) -> 20
A9: United Kingdom | B9: 33184 | C9: -29494 | D9: 52702 | E9: Tons | F9: 630 | G9: 43 | H9: 44 | I9: 19 | J9: 3.3 | K9: 789 | L9: 0.37 | M9: 1.1 | O9: Türkiye | P9: =VLOOKUP(Table12[[#This Row],[target]],Table1_111[#All],4,0) -> 25858 | Q9: =VLOOKUP(Table12[[#This Row],[target]],Table1_111[#All],2,0) -> 13886 | R9: =VLOOKUP(Table12[[#This Row],[target]],Table1_111[#All],12,0) -> 0.46 | S9: 785 | T9: =VLOOKUP(Table12[[#This Row],[target]],Table1_111[#All],7,0) -> -4 | U9: =VLOOKUP(Table12[[#This Row],[target]],Table1917[#All],7,0) -> Export | V9: =IF(Table12[[#This Row],[Distance between target and egypy]]<=2000,"Close",IF(Table12[[#This Row],[Distance between target and egypy]]<=4000,"Medium","Far")) -> Close | X9: Netherlands | Y9: =VLOOKUP(Table14[[#This Row],[Compitatores]],Table1_111[#All],9,0) -> -12
A10: Belgium | B10: 27445 | C10: 108092 | D10: 46793 | E10: Tons | F10: 587 | G10: 11 | H10: 15 | I10: -11 | J10: 2.7 | K10: 863 | L10: 0.28 | M10: 1.8 | O10: Russian Federation | P10: =VLOOKUP(Table12[[#This Row],[target]],Table1_111[#All],4,0) -> 40368 | Q10: =VLOOKUP(Table12[[#This Row],[target]],Table1_111[#All],2,0) -> 9204 | R10: =VLOOKUP(Table12[[#This Row],[target]],Table1_111[#All],12,0) -> 0.22 | S10: 2600 | T10: =VLOOKUP(Table12[[#This Row],[target]],Table1_111[#All],7,0) -> 17 | U10: =VLOOKUP(Table12[[#This Row],[target]],Table1917[#All],7,0) -> Export | V10: =IF(Table12[[#This Row],[Distance between target and egypy]]<=2000,"Close",IF(Table12[[#This Row],[Distance between target and egypy]]<=4000,"Medium","Far")) -> Medium | X10: China | Y10: =VLOOKUP(Table14[[#This Row],[Compitatores]],Table1_111[#All],9,0) -> -7
A11: Austria | B11: 26701 | C11: 4369 | D11: 48547 | E11: No quantity | F11: 550 | G11: 13 | H11: 4 | I11: 4 | J11: 2.6 | K11: 655 | L11: 0.39 | M11: 1.8 | O11: Italy | P11: =VLOOKUP(Table12[[#This Row],[target]],Table1_111[#All],4,0) -> 97632 | Q11: =VLOOKUP(Table12[[#This Row],[target]],Table1_111[#All],2,0) -> 50769 | R11: =VLOOKUP(Table12[[#This Row],[target]],Table1_111[#All],12,0) -> 0.19 | S11: 2200 | T11: =VLOOKUP(Table12[[#This Row],[target]],Table1_111[#All],7,0) -> 6 | U11: =VLOOKUP(Table12[[#This Row],[target]],Table1917[#All],7,0) -> Export | V11: =IF(Table12[[#This Row],[Distance between target and egypy]]<=2000,"Close",IF(Table12[[#This Row],[Distance between target and egypy]]<=4000,"Medium","Far")) -> Medium | X11: Israel | Y11: =VLOOKUP(Table14[[#This Row],[Compitatores]],Table1_111[#All],9,0) -> 10
A12: Netherlands | B12: 26482 | C12: 69914 | D12: 46337 | E12: Tons | F12: 572 | G12: 2 | H12: -8 | I12: -12 | J12: 2.6 | K12: 585 | L12: 0.47 | M12: 1.8 | O12: Germany | P12: =VLOOKUP(Table12[[#This Row],[target]],Table1_111[#All],4,0) -> 341423 | Q12: =VLOOKUP(Table12[[#This Row],[target]],Table1_111[#All],2,0) -> 91361 | R12: =VLOOKUP(Table12[[#This Row],[target]],Table1_111[#All],12,0) -> 0.26 | S12: 5925 | T12: =VLOOKUP(Table12[[#This Row],[target]],Table1_111[#All],7,0) -> 8 | U12: =VLOOKUP(Table12[[#This Row],[target]],Table1917[#All],7,0) -> Export | V12: =IF(Table12[[#This Row],[Distance between target and egypy]]<=2000,"Close",IF(Table12[[#This Row],[Distance between target and egypy]]<=4000,"Medium","Far")) -> Far | X12: Austria | Y12: =VLOOKUP(Table14[[#This Row],[Compitatores]],Table1_111[#All],9,0) -> 4
A13: Ireland | B13: 24830 | C13: -24572 | D13: 17230 | E13: Tons | F13: 1441 | G13: 17 | H13: -3 | I13: -4 | J13: 2.4 | K13: 2900 | L13: 0.5 | M13: 1.8 | O13: United Arab Emirates | P13: =VLOOKUP(Table12[[#This Row],[target]],Table1_111[#All],4,0) -> 5952 | Q13: =VLOOKUP(Table12[[#This Row],[target]],Table1_111[#All],2,0) -> 3245 | R13: =VLOOKUP(Table12[[#This Row],[target]],Table1_111[#All],12,0) -> 0.26 | S13: 4075 | T13: =VLOOKUP(Table12[[#This Row],[target]],Table1_111[#All],7,0) -> 6 | U13: =VLOOKUP(Table12[[#This Row],[target]],Table1917[#All],7,0) -> Export | V13: =IF(Table12[[#This Row],[Distance between target and egypy]]<=2000,"Close",IF(Table12[[#This Row],[Distance between target and egypy]]<=4000,"Medium","Far")) -> Far | X13: Sweden | Y13: =VLOOKUP(Table14[[#This Row],[Compitatores]],Table1_111[#All],9,0) -> 30
A14: Mexico | B14: 24112 | C14: -23263 | D14: 44997 | E14: Tons | F14: 536 | G14: 4 | H14: 1 | I14: 6 | J14: 2.4 | K14: 1635 | L14: 1 | M14: 0 | O14: South Africa | P14: =VLOOKUP(Table12[[#This Row],[target]],Table1_111[#All],4,0) -> 10651 | Q14: =VLOOKUP(Table12[[#This Row],[target]],Table1_111[#All],2,0) -> 5792 | R14: =VLOOKUP(Table12[[#This Row],[target]],Table1_111[#All],12,0) -> 0.29 | S14: 6850 | T14: =VLOOKUP(Table12[[#This Row],[target]],Table1_111[#All],7,0) -> 6 | U14: =VLOOKUP(Table12[[#This Row],[target]],Table1917[#All],7,0) -> Not | V14: =IF(Table12[[#This Row],[Distance between target and egypy]]<=2000,"Close",IF(Table12[[#This Row],[Distance between target and egypy]]<=4000,"Medium","Far")) -> Far | X14: France | Y14: =VLOOKUP(Table14[[#This Row],[Compitatores]],Table1_111[#All],9,0) -> 3
A15: Indonesia | B15: 22859 | C15: -10206 | D15: 49812 | E15: Tons | F15: 459 | G15: 11 | H15: 8 | I15: 7 | J15: 2.2 | K15: 3575 | L15: 0.33 | M15: 4.6 | O15: Pakistan | P15: =VLOOKUP(Table12[[#This Row],[target]],Table1_111[#All],4,0) -> 10584 | Q15: =VLOOKUP(Table12[[#This Row],[target]],Table1_111[#All],2,0) -> 4965 | R15: =VLOOKUP(Table12[[#This Row],[target]],Table1_111[#All],12,0) -> 0.51 | S15: 4275 | T15: =VLOOKUP(Table12[[#This Row],[target]],Table1_111[#All],7,0) -> 5 | U15: =VLOOKUP(Table12[[#This Row],[target]],Table1917[#All],7,0) -> Not | V15: =IF(Table12[[#This Row],[Distance between target and egypy]]<=2000,"Close",IF(Table12[[#This Row],[Distance between target and egypy]]<=4000,"Medium","Far")) -> Far | X15: Germany | Y15: =VLOOKUP(Table14[[#This Row],[Compitatores]],Table1_111[#All],9,0) -> -9
A16: Portugal | B16: 22266 | C16: -19119 | D16: 37739 | E16: No quantity | F16: 590 | G16: 12 | H16: 4 | I16: -1 | J16: 2.2 | K16: 1604 | L16: 0.22 | M16: 1.8 | O16: Morocco | P16: =VLOOKUP(Table12[[#This Row],[target]],Table1_111[#All],4,0) -> 2863 | Q16: =VLOOKUP(Table12[[#This Row],[target]],Table1_111[#All],2,0) -> 2021 | R16: =VLOOKUP(Table12[[#This Row],[target]],Table1_111[#All],12,0) -> 0.26 | S16: 3750 | T16: =VLOOKUP(Table12[[#This Row],[target]],Table1_111[#All],7,0) -> -2 | U16: =VLOOKUP(Table12[[#This Row],[target]],Table1917[#All],7,0) -> Not | V16: =IF(Table12[[#This Row],[Distance between target and egypy]]<=2000,"Close",IF(Table12[[#This Row],[Distance between target and egypy]]<=4000,"Medium","Far")) -> Medium | X16: Türkiye | Y16: =VLOOKUP(Table14[[#This Row],[Compitatores]],Table1_111[#All],9,0) -> -13
A17: Singapore | B17: 22002 | C17: -9505 | D17: 27871 | E17: Tons | F17: 789 | G17: 13 | H17: 8 | I17: 12 | J17: 2.2 | K17: 1722 | L17: 0.39 | M17: 0 | O17: Algeria | P17: =VLOOKUP(Table12[[#This Row],[target]],Table1_111[#All],4,0) -> 2945 | Q17: =VLOOKUP(Table12[[#This Row],[target]],Table1_111[#All],2,0) -> 1964 | R17: =VLOOKUP(Table12[[#This Row],[target]],Table1_111[#All],12,0) -> 0.24 | S17: 2650 | T17: =VLOOKUP(Table12[[#This Row],[target]],Table1_111[#All],7,0) -> 21 | U17: =VLOOKUP(Table12[[#This Row],[target]],Table1917[#All],7,0) -> Not | V17: =IF(Table12[[#This Row],[Distance between target and egypy]]<=2000,"Close",IF(Table12[[#This Row],[Distance between target and egypy]]<=4000,"Medium","Far")) -> Medium
A18: Chile | B18: 21184 | C18: -20096 | D18: 48505 | E18: Tons | F18: 437 | G18: -3 | H18: -6 | I18: -11 | J18: 2.1 | K18: 4114 | L18: 0.85 | M18: 3.2 | O18: Indonesia | P18: =VLOOKUP(Table12[[#This Row],[target]],Table1_111[#All],4,0) -> 49812 | Q18: =VLOOKUP(Table12[[#This Row],[target]],Table1_111[#All],2,0) -> 22859 | R18: =VLOOKUP(Table12[[#This Row],[target]],Table1_111[#All],12,0) -> 0.33 | S18: 8700 | T18: =VLOOKUP(Table12[[#This Row],[target]],Table1_111[#All],7,0) -> 11 | U18: =VLOOKUP(Table12[[#This Row],[target]],Table1917[#All],7,0) -> Export | V18: =IF(Table12[[#This Row],[Distance between target and egypy]]<=2000,"Close",IF(Table12[[#This Row],[Distance between target and egypy]]<=4000,"Medium","Far")) -> Far
A19: Spain | B19: 19724 | C19: -10783 | D19: 38675 | E19: No quantity | F19: 510 | G19: 11 | H19: 4 | I19: 26 | J19: 1.9 | K19: 1241 | L19: 0.2 | M19: 1.8 | S19: =MEDIAN(Table12[Distance between target and egypy]) -> 4075 | T19: =MEDIAN(Table12[growth]) -> 8
A20: Czech Republic | B20: 19180 | C20: -18583 | D20: 39958 | E20: No quantity | F20: 480 | G20: 7 | H20: 4 | I20: 11 | J20: 1.9 | K20: 499 | L20: 0.61 | M20: 1.8 | O20: Which markets achieve the highest Export Attractiveness Index?
A21: Peru | B21: 17334 | C21: -17327 | D21: 28472 | E21: Tons | F21: 609 | G21: 11 | H21: 3 | I21: -9 | J21: 1.7 | K21: 5979 | L21: 0.56 | M21: 0 | O21: target | P21: conc | Q21: distance | R21: quantity | S21: growth | T21: score | U21: final target
A22: Argentina | B22: 17123 | C22: -17123 | D22: 24420 | E22: Tons | F22: 701 | G22: 0 | H22: -7 | I22: -25 | J22: 1.7 | K22: 3340 | L22: 0.65 | M22: 9.5 | O22: Germany | P22: 1 | Q22: -1 | R22: 1 | S22: 0 | T22: =SUM(Table1917[[#This Row],[conc]],Table1917[[#This Row],[distance ]],Table1917[[#This Row],[quantity ]],Table1917[[#This Row],[growth ]]) -> 1 | U22: =IF(Table1917[[#This Row],[score]]>=0,"Export","Not") -> Export | W22: avg growth in target market 8
A23: India | B23: 16016 | C23: -4412 | D23: 46171 | E23: Tons | F23: 347 | G23: 3 | H23: 8 | I23: -4 | J23: 1.6 | K23: 1616 | L23: 0.67 | M23: 5.9 | O23: Italy | P23: 1 | Q23: 1 | R23: 1 | S23: 0 | T23: =SUM(Table1917[[#This Row],[conc]],Table1917[[#This Row],[distance ]],Table1917[[#This Row],[quantity ]],Table1917[[#This Row],[growth ]]) -> 3 | U23: =IF(Table1917[[#This Row],[score]]>=0,"Export","Not") -> Export
A24: China | B24: 15912 | C24: -5068 | D24: 17749 | E24: Tons | F24: 897 | G24: -20 | H24: -23 | I24: -7 | J24: 1.6 | K24: 2454 | L24: 0.37 | M24: 5.9 | O24: Indonesia | P24: 1 | Q24: -1 | R24: 1 | S24: 0 | T24: =SUM(Table1917[[#This Row],[conc]],Table1917[[#This Row],[distance ]],Table1917[[#This Row],[quantity ]],Table1917[[#This Row],[growth ]]) -> 1 | U24: =IF(Table1917[[#This Row],[score]]>=0,"Export","Not") -> Export
A25: Sweden | B25: 15121 | C25: 37147 | D25: 42683 | E25: Tons | F25: 354 | G25: -4 | H25: 0 | I25: 30 | J25: 1.5 | K25: 585 | L25: 0.53 | M25: 1.8 | O25: India | P25: 1 | Q25: -1 | R25: 1 | S25: -1 | T25: =SUM(Table1917[[#This Row],[conc]],Table1917[[#This Row],[distance ]],Table1917[[#This Row],[quantity ]],Table1917[[#This Row],[growth ]]) -> 0 | U25: =IF(Table1917[[#This Row],[score]]>=0,"Export","Not") -> Export
A26: Switzerland | B26: 14334 | C26: -12728 | D26: 18980 | E26: Tons | F26: 755 | G26: 5 | H26: -3 | I26: -18 | J26: 1.4 | K26: 600 | L26: 0.32 | M26: 0 | O26: Russian Federation | P26: 0 | Q26: 1 | R26: 1 | S26: 1 | T26: =SUM(Table1917[[#This Row],[conc]],Table1917[[#This Row],[distance ]],Table1917[[#This Row],[quantity ]],Table1917[[#This Row],[growth ]]) -> 3 | U26: =IF(Table1917[[#This Row],[score]]>=0,"Export","Not") -> Export
A27: Türkiye | B27: 13886 | C27: -784 | D27: 25858 | E27: No quantity | F27: 537 | G27: -4 | H27: 4 | I27: -13 | J27: 1.4 | K27: 2489 | L27: 0.46 | M27: 2.7 | O27: Türkiye | P27: 1 | Q27: 1 | R27: 0 | S27: -1 | T27: =SUM(Table1917[[#This Row],[conc]],Table1917[[#This Row],[distance ]],Table1917[[#This Row],[quantity ]],Table1917[[#This Row],[growth ]]) -> 1 | U27: =IF(Table1917[[#This Row],[score]]>=0,"Export","Not") -> Export
A28: Malaysia | B28: 13109 | C28: -12460 | D28: 19624 | E28: Tons | F28: 668 | G28: 2 | H28: -3 | I28: -17 | J28: 1.3 | K28: 2721 | L28: 0.22 | M28: 0 | O28: Jordan | P28: 0 | Q28: 1 | R28: 0 | S28: 0 | T28: =SUM(Table1917[[#This Row],[conc]],Table1917[[#This Row],[distance ]],Table1917[[#This Row],[quantity ]],Table1917[[#This Row],[growth ]]) -> 1 | U28: =IF(Table1917[[#This Row],[score]]>=0,"Export","Not") -> Export
A29: Colombia | B29: 12760 | C29: -12713 | D29: 21046 | E29: Tons | F29: 606 | G29: 2 | H29: -3 | I29: -8 | J29: 1.3 | K29: 5022 | L29: 0.61 | M29: 0 | O29: South Africa | P29: 0 | Q29: -1 | R29: 0 | S29: -1 | T29: =SUM(Table1917[[#This Row],[conc]],Table1917[[#This Row],[distance ]],Table1917[[#This Row],[quantity ]],Table1917[[#This Row],[growth ]]) -> -2 | U29: =IF(Table1917[[#This Row],[score]]>=0,"Export","Not") -> Not
A30: Canada | B30: 11868 | C30: 31469 | D30: 6416 | E30: Tons | F30: 1850 | G30: -7 | H30: -18 | I30: 5 | J30: 1.2 | K30: 2323 | L30: 0.65 | M30: 0.3 | O30: Pakistan | P30: 0 | Q30: 0 | R30: 0 | S30: -1 | T30: =SUM(Table1917[[#This Row],[conc]],Table1917[[#This Row],[distance ]],Table1917[[#This Row],[quantity ]],Table1917[[#This Row],[growth ]]) -> -1 | U30: =IF(Table1917[[#This Row],[score]]>=0,"Export","Not") -> Not
A31: Poland | B31: 11640 | C31: -6995 | D31: 25554 | E31: Tons | F31: 456 | G31: 10 | H31: 5 | I31: -14 | J31: 1.1 | K31: 836 | L31: 0.23 | M31: 1.8 | O31: United Arab Emirates | P31: 0 | Q31: 0 | R31: 0 | S31: 0 | T31: =SUM(Table1917[[#This Row],[conc]],Table1917[[#This Row],[distance ]],Table1917[[#This Row],[quantity ]],Table1917[[#This Row],[growth ]]) -> 0 | U31: =IF(Table1917[[#This Row],[score]]>=0,"Export","Not") -> Export
A32: Japan | B32: 10298 | C32: 6183 | D32: 23294 | E32: Tons | F32: 442 | G32: -1 | H32: 3 | I32: 8 | J32: 1 | K32: 1338 | L32: 0.75 | M32: 0.9 | O32: Algeria | P32: -1 | Q32: 0 | R32: -1 | S32: 1 | T32: =SUM(Table1917[[#This Row],[conc]],Table1917[[#This Row],[distance ]],Table1917[[#This Row],[quantity ]],Table1917[[#This Row],[growth ]]) -> -1 | U32: =IF(Table1917[[#This Row],[score]]>=0,"Export","Not") -> Not
A33: Ecuador | B33: 9890 | C33: -9497 | D33: 18215 | E33: Tons | F33: 543 | G33: 3 | H33: 3 | I33: -51 | J33: 1 | K33: 7679 | L33: 0.51 | M33: 0 | O33: Morocco | P33: -1 | Q33: 0 | R33: -1 | S33: -1 | T33: =SUM(Table1917[[#This Row],[conc]],Table1917[[#This Row],[distance ]],Table1917[[#This Row],[quantity ]],Table1917[[#This Row],[growth ]]) -> -3 | U33: =IF(Table1917[[#This Row],[score]]>=0,"Export","Not") -> Not
A34: Russian Federation | B34: 9204 | C34: -5721 | D34: 40368 | E34: No quantity | F34: 228 | G34: 17 | H34: 4 | I34: -71 | J34: 0.9 | K34: 4037 | L34: 0.22 | M34: 4.8 | O34: Uganda | P34: -1 | Q34: 0 | R34: -1 | S34: 1 | T34: =SUM(Table1917[[#This Row],[conc]],Table1917[[#This Row],[distance ]],Table1917[[#This Row],[quantity ]],Table1917[[#This Row],[growth ]]) -> -1 | U34: =IF(Table1917[[#This Row],[score]]>=0,"Export","Not") -> Not
... A36: Australia | B36: 8648 | C36: -5223 | D36: 17053 | E36: Tons | F36: 507 | G36: 27 | H36: 24 | I36: -5 | J36: 0.8 | K36: 7318 | L36: 0.24 | M36: 3.1 | O36: Cyprus | P36: -1 | Q36: 1 | R36: -1 | S36: 1 | T36: =SUM(Table1917[[#This Row],[conc]],Table1917[[#This Row],[distance ]],Table1917[[#This Row],[quantity ]],Table1917[[#This Row],[growth ]]) -> 0 | U36: =IF(Table1917[[#This Row],[score]]>=0,"Export","Not") -> Export
A37: Jordan | B37: 8513 | C37: -8513 | D37: 14991 | E37: Tons | F37: 568 | G37: 13 | H37: 13 | I37: 2 | J37: 0.8 | K37: 1601 | L37: 0.46 | M37: 0
A38: Slovakia | B38: 7397 | C38: -7086 | D38: 15572 | E38: No quantity | F38: 475 | G38: 0 | H38: 4 | I38: 0 | J38: 0.7 | K38: 895 | L38: 0.43 | M38: 1.8
A39: Estonia | B39: 7283 | C39: -7254 | D39: 14280 | E39: No quantity | F39: 510 | G39: -6 | H39: 4 | I39: 1 | J39: 0.7 | K39: 491 | L39: 0.4 | M39: 1.8
A40: Hungary | B40: 6809 | C40: -6135 | D40: 14692 | E40: Tons | F40: 463 | G40: 2 | H40: -2 | I40: 28 | J40: 0.7 | K40: 459 | L40: 0.28 | M40: 1.8
A41: Norway | B41: 6408 | C41: -2764 | D41: 13367 | E41: Tons | F41: 479 | G41: -15 | H41: -12 | I41: 7 | J41: 0.6 | K41: 683 | L41: 0.48 | M41: 0
...

Sheet Pivot5
A1: Phase 5
A2: How can each target market be evaluated based on factors such as market size, market growth, competition intensity, distance, and tariffs?
A3: Row Labels | B3: Sum of value | C3: Sum of quantity
A4: Germany | B4: 91361 | C4: 341423
A5: India | B5: 16016 | C5: 46171
A6: Indonesia | B6: 22859 | C6: 49812
A7: Madagascar | B7: 228 | C7: 393
A8: Pakistan | B8: 4965 | C8: 10584
A9: South Africa | B9: 5792 | C9: 10651
A10: Uganda | B10: 559 | C10: 1243
A11: United Arab Emirates | B11: 3245 | C11: 5952
A12: Grand Total | B12: 145025 | C12: 466229
C20: =GETPIVOTDATA("Sum of quantity",$A$3) -> 466229
A24: Row Labels | B24: Sum of supplyconc
A25: Germany | B25: 0.26
A26: India | B26: 0.67
A27: Indonesia | B27: 0.33
A28: Madagascar | B28: 0.5
A29: Pakistan | B29: 0.51
A30: South Africa | B30: 0.29
A31: Uganda | B31: 0.32
A32: United Arab Emirates | B32: 0.26
A33: Grand Total | B33: 3.14
B41: =GETPIVOTDATA("supplyconc",$A$24) -> 3.14
A43: Row Labels | B43: Sum of Distance between target and egypy
A44: Indonesia | B44: 8700
A45: South Africa | B45: 6850
A46: Madagascar | B46: 6667
A47: Germany | B47: 5925
A48: India | B48: 5200
A49: Uganda | B49: 4650
A50: Pakistan | B50: 4275
A51: United Arab Emirates | B51: 4075
A52: Morocco | B52: 3750
A53: Algeria | B53: 2650
A54: Russian Federation | B54: 2600
A55: Italy | B55: 2200
... A59: Grand Total | B59: 58930
B60: =GETPIVOTDATA("Distance between target and egypy",$A$43) -> 58930
A65: Row Labels | B65: Sum of growth
...

Sheet Clean Data 
A1: Importers | B1: Value imported in 2024 (USD thousand) | C1: Trade balance in 2024 (USD thousand) | D1: Quantity imported in 2024 | E1: Quantity Unit | F1: Unit value (USD/unit) | G1: Annual growth in value between 2020-2024 (%) | H1: Annual growth in quantity between 2020-2024 (%) | I1: Annual growth in value between 2023-2024 (%) | J1: Share in world imports (%) | K1: Average distance of supplying countries (km) | L1: Concentration of supplying countries | M1: Average tariff (estimated) applied by the country (%) | N1: Concerterntion astrans | O1: Region | P1: Growth | Q1: Traiff Catrgey
A2: Germany | B2: 91361 | C2: -25985 | D2: 341423 | E2: Tons | F2: 268 | G2: 8 | H2: 16 | I2: -9 | J2: 9 | K2: 660 | L2: 0.26 | M2: 1.8 | N2: =IF(Table1_14[[#This Row],[Concentration of supplying countries]]>0.5,"Manoply","Not Manoply") -> Not Manoply | O2: Western/Central Europe | P2: =IF(Table1_14[[#This Row],[Annual growth in quantity between 2020-2024 (%)]]>10%,"High Growth", IF(Table1_14[[#This Row],[Annual growth in quantity between 2020-2024 (%)]]>0,"Stable","Decline")) -> High Growth | Q2: =IF(Table1_14[[#This Row],[Average tariff (estimated) applied by the country (%)]]>1.8,"High","Low") -> Low
A3: United States of America | B3: 54248 | C3: -13806 | D3: 105800 | E3: Tons | F3: 513 | G3: 5 | H3: 3 | I3: 28 | J3: 5.3 | K3: 2918 | L3: 0.64 | M3: 1.8 | N3: =IF(Table1_14[[#This Row],[Concentration of supplying countries]]>0.5,"Manoply","Not Manoply") -> Manoply | O3: North America | P3: =IF(Table1_14[[#This Row],[Annual growth in quantity between 2020-2024 (%)]]>10%,"High Growth", IF(Table1_14[[#This Row],[Annual growth in quantity between 2020-2024 (%)]]>0,"Stable","Decline")) -> High Growth | Q3: =IF(Table1_14[[#This Row],[Average tariff (estimated) applied by the country (%)]]>1.8,"High","Low") -> Low
A4: Italy | B4: 50769 | C4: -50762 | D4: 97632 | E4: No quantity | F4: 520 | G4: 6 | H4: 4 | I4: 2 | J4: 5 | K4: 825 | L4: 0.19 | M4: 1.8 | N4: =IF(Table1_14[[#This Row],[Concentration of supplying countries]]>0.5,"Manoply","Not Manoply") -> Not Manoply | O4: Southern Europe | P4: =IF(Table1_14[[#This Row],[Annual growth in quantity between 2020-2024 (%)]]>10%,"High Growth", IF(Table1_14[[#This Row],[Annual growth in quantity between 2020-2024 (%)]]>0,"Stable","Decline")) -> High Growth | Q4: =IF(Table1_14[[#This Row],[Average tariff (estimated) applied by the country (%)]]>1.8,"High","Low") -> Low
A5: France | B5: 41958 | C5: -2345 | D5: 62054 | E5: Tons | F5: 676 | G5: 8 | H5: 0 | I5: 3 | J5: 4.1 | K5: 689 | L5: 0.25 | M5: 1.8 | N5: =IF(Table1_14[[#This Row],[Concentration of supplying countries]]>0.5,"Manoply","Not Manoply") -> Not Manoply | O5: Western Europe | P5: =IF(Table1_14[[#This Row],[Annual growth in quantity between 2020-2024 (%)]]>10%,"High Growth", IF(Table1_14[[#This Row],[Annual growth in quantity between 2020-2024 (%)]]>0,"Stable","Decline")) -> Decline | Q5: =IF(Table1_14[[#This Row],[Average tariff (estimated) applied by the country (%)]]>1.8,"High","Low") -> Low
A6: Israel | B6: 38792 | C6: -33359 | D6: 62769 | E6: Tons | F6: 618 | G6: 13 | H6: 4 | I6: 10 | J6: 3.8 | K6: 3515 | L6: 0.46 | M6: 1.8 | N6: =IF(Table1_14[[#This Row],[Concentration of supplying countries]]>0.5,"Manoply","Not Manoply") -> Not Manoply | O6: Western Asia (Middle East) | P6: =IF(Table1_14[[#This Row],[Annual growth in quantity between 2020-2024 (%)]]>10%,"High Growth", IF(Table1_14[[#This Row],[Annual growth in quantity between 2020-2024 (%)]]>0,"Stable","Decline")) -> High Growth | Q6: =IF(Table1_14[[#This Row],[Average tariff (estimated) applied by the country (%)]]>1.8,"High","Low") -> Low
A7: Viet Nam | B7: 34586 | C7: -33906 | D7: 55396 | E7: Tons | F7: 624 | G7: 9 | H7: 1 | I7: -9 | J7: 3.4 | K7: 1916 | L7: 0.31 | M7: 2.1 | N7: =IF(Table1_14[[#This Row],[Concentration of supplying countries]]>0.5,"Manoply","Not Manoply") -> Not Manoply | O7: Southeast Asia | P7: =IF(Table1_14[[#This Row],[Annual growth in quantity between 2020-2024 (%)]]>10%,"High Growth", IF(Table1_14[[#This Row],[Annual growth in quantity between 2020-2024 (%)]]>0,"Stable","Decline")) -> High Growth | Q7: =IF(Table1_14[[#This Row],[Average tariff (estimated) applied by the country (%)]]>1.8,"High","Low") -> High
A8: Taipei, Chinese | B8: 33727 | C8: -27402 | D8: 52012 | E8: Tons | F8: 648 | G8: -7 | H8: -12 | I8: -15 | J8: 3.3 | K8: 1880 | L8: 0.42 | M8: 4.1 | N8: =IF(Table1_14[[#This Row],[Concentration of supplying countries]]>0.5,"Manoply","Not Manoply") -> Not Manoply | O8: East Asia | P8: =IF(Table1_14[[#This Row],[Annual growth in quantity between 2020-2024 (%)]]>10%,"High Growth", IF(Table1_14[[#This Row],[Annual growth in quantity between 2020-2024 (%)]]>0,"Stable","Decline")) -> Decline | Q8: =IF(Table1_14[[#This Row],[Average tariff (estimated) applied by the country (%)]]>1.8,"High","Low") -> High
A9: United Kingdom | B9: 33184 | C9: -29494 | D9: 52702 | E9: Tons | F9: 630 | G9: 43 | H9: 44 | I9: 19 | J9: 3.3 | K9: 789 | L9: 0.37 | M9: 1.1 | N9: =IF(Table1_14[[#This Row],[Concentration of supplying countries]]>0.5,"Manoply","Not Manoply") -> Not Manoply | O9: Western Europe | P9: =IF(Table1_14[[#This Row],[Annual growth in quantity between 2020-2024 (%)]]>10%,"High Growth", IF(Table1_14[[#This Row],[Annual growth in quantity between 2020-2024 (%)]]>0,"Stable","Decline")) -> High Growth | Q9: =IF(Table1_14[[#This Row],[Average tariff (estimated) applied by the country (%)]]>1.8,"High","Low") -> Low
A10: Belgium | B10: 27445 | C10: 108092 | D10: 46793 | E10: Tons | F10: 587 | G10: 11 | H10: 15 | I10: -11 | J10: 2.7 | K10: 863 | L10: 0.28 | M10: 1.8 | N10: =IF(Table1_14[[#This Row],[Concentration of supplying countries]]>0.5,"Manoply","Not Manoply") -> Not Manoply | O10: Western Europe | P10: =IF(Table1_14[[#This Row],[Annual growth in quantity between 2020-2024 (%)]]>10%,"High Growth", IF(Table1_14[[#This Row],[Annual growth in quantity between 2020-2024 (%)]]>0,"Stable","Decline")) -> High Growth | Q10: =IF(Table1_14[[#This Row],[Average tariff (estimated) applied by the country (%)]]>1.8,"High","Low") -> Low
A11: Austria | B11: 26701 | C11: 4369 | D11: 48547 | E11: No quantity | F11: 550 | G11: 13 | H11: 4 | I11: 4 | J11: 2.6 | K11: 655 | L11: 0.39 | M11: 1.8 | N11: =IF(Table1_14[[#This Row],[Concentration of supplying countries]]>0.5,"Manoply","Not Manoply") -> Not Manoply | O11: Western/Central Europe | P11: =IF(Table1_14[[#This Row],[Annual growth in quantity between 2020-2024 (%)]]>10%,"High Growth", IF(Table1_14[[#This Row],[Annual growth in quantity between 2020-2024 (%)]]>0,"Stable","Decline")) -> High Growth | Q11: =IF(Table1_14[[#This Row],[Average tariff (estimated) applied by the country (%)]]>1.8,"High","Low") -> Low
A12: Netherlands | B12: 26482 | C12: 69914 | D12: 46337 | E12: Tons | F12: 572 | G12: 2 | H12: -8 | I12: -12 | J12: 2.6 | K12: 585 | L12: 0.47 | M12: 1.8 | N12: =IF(Table1_14[[#This Row],[Concentration of supplying countries]]>0.5,"Manoply","Not Manoply") -> Not Manoply | O12: Western Europe | P12: =IF(Table1_14[[#This Row],[Annual growth in quantity between 2020-2024 (%)]]>10%,"High Growth", IF(Table1_14[[#This Row],[Annual growth in quantity between 2020-2024 (%)]]>0,"Stable","Decline")) -> Decline | Q12: =IF(Table1_14[[#This Row],[Average tariff (estimated) applied by the country (%)]]>1.8,"High","Low") -> Low
A13: Ireland | B13: 24830 | C13: -24572 | D13: 17230 | E13: Tons | F13: 1441 | G13: 17 | H13: -3 | I13: -4 | J13: 2.4 | K13: 2900 | L13: 0.5 | M13: 1.8 | N13: =IF(Table1_14[[#This Row],[Concentration of supplying countries]]>0.5,"Manoply","Not Manoply") -> Not Manoply | O13: Western Europe | P13: =IF(Table1_14[[#This Row],[Annual growth in quantity between 2020-2024 (%)]]>10%,"High Growth", IF(Table1_14[[#This Row],[Annual growth in quantity between 2020-2024 (%)]]>0,"Stable","Decline")) -> Decline | Q13: =IF(Table1_14[[#This Row],[Average tariff (estimated) applied by the country (%)]]>1.8,"High","Low") -> Low
... A172: Sao Tome and Principe | B172: 5 | C172: -5 | D172: 3 | E172: Tons | F172: 1667 | G172: 6 | H172: 1 | I172: 132 | J172: 0 | K172: 4615 | L172: 1 | M172: 5 | N172: =IF(Table1_14[[#This Row],[Concentration of supplying countries]]>0.5,"Manoply","Not Manoply") -> Manoply | O172: Central Africa | P172: =IF(Table1_14[[#This Row],[Annual growth in quantity between 2020-2024 (%)]]>10%,"High Growth", IF(Table1_14[[#This Row],[Annual growth in quantity between 2020-2024 (%)]]>0,"Stable","Decline")) -> High Growth | Q172: =IF(Table1_14[[#This Row],[Average tariff (estimated) applied by the country (%)]]>1.8,"High","Low") -> High

Sheet Dashboard

Sheet Map
A1: Target | B1: Value
A2: =Pivot5!A4 -> Germany | B2: =GETPIVOTDATA("Sum of value",Pivot5!$B$4,"target",A2) -> 91361
A3: =Pivot5!A5 -> India | B3: =GETPIVOTDATA("Sum of value",Pivot5!$B$4,"target",A3) -> 16016
A4: =Pivot5!A6 -> Indonesia | B4: =GETPIVOTDATA("Sum of value",Pivot5!$B$4,"target",A4) -> 22859
A5: =Pivot5!A7 -> Madagascar | B5: =GETPIVOTDATA("Sum of value",Pivot5!$B$4,"target",A5) -> 228
A6: =Pivot5!A8 -> Pakistan | B6: =GETPIVOTDATA("Sum of value",Pivot5!$B$4,"target",A6) -> 4965
A7: =Pivot5!A9 -> South Africa | B7: =GETPIVOTDATA("Sum of value",Pivot5!$B$4,"target",A7) -> 5792
A8: =Pivot5!A10 -> Uganda | B8: =GETPIVOTDATA("Sum of value",Pivot5!$B$4,"target",A8) -> 559
A9: =Pivot5!A11 -> United Arab Emirates | B9: =GETPIVOTDATA("Sum of value",Pivot5!$B$4,"target",A9) -> 3245
A10: =Pivot5!A12 -> Grand Total | B10: =GETPIVOTDATA("Sum of value",Pivot5!$B$4,"target",A10) -> #REF!
A11: =Pivot5!A13 -> 0 | B11: =GETPIVOTDATA("Sum of value",Pivot5!$B$4,"target",A11) -> #REF!
A12: =Pivot5!A14 -> 0 | B12: =GETPIVOTDATA("Sum of value",Pivot5!$B$4,"target",A12) -> #REF!
A13: =Pivot5!A15 -> 0 | B13: =GETPIVOTDATA("Sum of value",Pivot5!$B$4,"target",A13) -> #REF!
... A16: =Pivot5!A18 -> 0 | B16: =GETPIVOTDATA("Sum of value",Pivot5!$B$4,"target",A16) -> #REF!
